<?xml version="1.0"?>
<robot name="simple_bot" xmlns:xacro="http://www.ros.org/wiki/xacro">

<!-- Pi constant -->
<xacro:property name="pi_const" value="3.14159265"/>

<!-- Body dimensions -->
<xacro:property name="a" value="1.0"/>
<xacro:property name="b" value="0.3"/>
<xacro:property name="c" value="0.6"/>


<!-- Wheel and caster dimensions -->
<!-- wheel and caster radius -->
<xacro:property name="r" value="0.15"/>
<!-- wheel width -->
<xacro:property name="d" value="0.1"/>

<xacro:property name="s1" value="${b/2+r}"/>
<xacro:property name="s2" value="${2*r}"/>
<xacro:property name="s3" value="${2*r}"/>
<xacro:property name="s4" value="${c/2+d/2}"/>

<!-- ############################################################ -->
<!-- Mass and inertia -->
<!-- ############################################################ -->

<!-- material density -->
<!-- body material density -->
<xacro:property name="d1" value="2710.0"/>
<!-- wheel material density -->
<xacro:property name="d2" value="2710.0"/>
<!-- caster material density -->
<xacro:property name="d3" value="2710.0"/>

<!-- Robot body mass, wheel mass, caster mass -->
<!-- body -->
<xacro:property name="m1" value="${d1*a*b*c}"/>
<!-- wheel -->
<xacro:property name="m2" value="${d2*pi_const*r*r*d}"/>
<!-- caster -->
<xacro:property name="m3" value="${d3*(4.0/3.0)*pi_const*r*r*r}"/>

<!-- Moments of inertia for the robot body -->
<xacro:property name="Ix_body" value="${(1/12)*m1*(b*b+c*c)}"/>
<xacro:property name="Iy_body" value="${(1/12)*m1*(a*a+b*b)}"/>
<xacro:property name="Iz_body" value="${(1/12)*m1*(a*a+c*c)}"/>

<!-- moments of inertia for the wheel -->
<xacro:property name="Iz_wheel" value="${0.5*m2*r*r}"/>
<xacro:property name="I_wheel" value="${(1.0/12.0)*m2*(3.0*r*r+d*d)}"/>

<!-- moments of inertia for the caster sphere -->
<xacro:property name="I_caster" value="${(2.0/5.0)*m3*r*r}"/>

<!-- macro to define complete inertial section of the robot body -->
<xacro:macro name="inertia_body">
    <inertial>
    <!-- displacement and orientation of the center of mass frame of the link with respect to the coordinate plane -->
    <!-- rpy stands for roll pitch yaw in the coordinate plane -->
    <origin rpy="0 0 0" xyz="0 0 ${s1}"/>
    <mass value="${m1}"/>
    <inertia ixx="${Ix_body}" ixy="0.0" ixz="0.0" iyy="${Iy_body}" iyz="0.0" izz="${Iz_body}"/>
    </inertial>
</xacro:macro>

<!-- macro to define complete inertial section of the wheel -->
<xacro:macro name="inertia_wheel">
    <inertial>
    <!-- rotation around the x axis for the wheels represented in radians (its pi/2) -->
    <origin rpy="1.570795 0 0" xyz="0 0 0"/>
    <mass value="${m2}"/>
    <inertia ixx="${I_wheel}" ixy="0.0" ixz="0.0" iyy="${I_wheel}" iyz="0.0" izz="${Iz_wheel}"/>
    </inertial>
</xacro:macro>

<!-- macro to define complete inertial section of the caster -->
<xacro:macro name="inertia_caster">
    <inertial>
    <origin rpy="0 0 0" xyz="0 0 0"/>
    <mass value="${m3}"/>
    <inertia ixx="${I_caster}" ixy="0.0" ixz="0.0" iyy="${I_caster}" iyz="0.0" izz="${I_caster}"/>
    </inertial>
</xacro:macro>

<!-- ############################################################### -->
<!-- Addidional files (needed for control) -->
<!-- ############################################################### -->
<!-- inside of the warehouse_gz package, in the models/simple_bot directory thats our file -->
<xacro:include filename="$(find warehouse_gz)/models/simple_bot/robot.gazebo"/>

<!-- ############################################################### -->
<!-- Links and joints defenitions -->
<!-- ############################################################### -->

<!-- link for gazebo (not actually a link) -->
<link name="base_footprint"> </link>
<joint name="body_link_joint" type="fixed">
    <parent link="base_footprint"/>
    <child link="body_link"/>
</joint>


<!-- body link -->
<link name="body_link">
    <visual>
        <geometry>
            <box size="${a} ${c} ${b}"/>
        </geometry>
    <!-- displacement and orientation of the geometric center of the link with respect to the parent link-->
    <origin rpy="0 0 0" xyz="0 0 ${s1}"/>
    </visual>

    <collision>
        <geometry>
            <box size="${a} ${c} ${b}"/>
        </geometry>
    <origin rpy="0 0 0" xyz="0 0 ${s1}"/>
    </collision>

    <xacro:inertia_body/>
</link>


<!-- back right wheel of the robot -->
<joint name="wheel1_joint" type="continuous">
    <parent link="body_link"/>
    <child link="wheel1_link"/>
    <origin rpy="0 0 0" xyz="${-s2} ${-s4} ${r}"/>
    <axis xyz="0 1 0"/>
    <limit effort="50000" velocity="10"/>
    <dynamics damping="1.0" friction="1.0"/>
</joint>

<link name="wheel1_link">
    <visual>
        <origin rpy="1.570795 0 0" xyz="0 0 0"/>
        <geometry>
            <cylinder length="${d}" radius="${r}"/>
        </geometry>
    </visual>

    <collision>
        <origin rpy="1.570795 0 0" xyz="0 0 0"/>
        <geometry>
            <cylinder length="${d}" radius="${r}"/>
        </geometry>
    </collision>

    <xacro:inertia_wheel/>
</link>

<!-- back left wheel of the robot -->
<joint name="wheel2_joint" type="continuous">
    <parent link="body_link"/>
    <child link="wheel2_link"/>
    <origin rpy="0 0 0" xyz="${-s2} ${s4} ${r}"/>
    <axis xyz="0 1 0"/>
    <limit effort="50000" velocity="10"/>
    <dynamics damping="1.0" friction="1.0"/>
</joint>

<link name="wheel2_link">
    <visual>
        <origin rpy="1.570795 0 0" xyz="0 0 0"/>
        <geometry>
            <cylinder length="${d}" radius="${r}"/>
        </geometry>
    </visual>

    <collision>
        <origin rpy="1.570795 0 0" xyz="0 0 0"/>
        <geometry>
            <cylinder length="${d}" radius="${r}"/>
        </geometry>
    </collision>

    <xacro:inertia_wheel/>
</link>

<!-- start caster wheel -->
<joint name="caster_joint" type="fixed">
    <parent link="body_link"/>
    <child link="caster_link"/>
    <origin rpy="0 0 0" xyz="${s3} 0 ${r}"/>
</joint>

<link name="caster_link">
    <visual>
        <origin rpy="0 0 0" xyz="0 0 0"/>
        <geometry>
            <sphere radius="${r}"/>
        </geometry>
    </visual>

    <collision>
        <origin rpy="0 0 0" xyz="0 0 0"/>
        <geometry>
            <sphere radius="${r}"/>
        </geometry>
    </collision>

    <xacro:inertia_caster/>
</link>


</robot>